Workbook
Name _À_Vista: #REF!
Name _al_PISCOFINS: #REF!
Name _AlçadaCdG: #REF!
Name _Classificacao: #REF!
Name _ClassificacaoLinha: #REF!
Name _CNPJsCliente: #REF!
Name _ContribuinteICMS: #REF!
Name _EquipeCDG: #REF!
Name _Estoque: #REF!
Name _Fabricante: #REF!
Name _Filiais: #REF!
Name _FiliaisRJ: #REF!
Name _FiliaisSP: #REF!
Name _Fornecedor: #REF!
Name _ICMS_Contr: #REF!
Name _ICMS_Próprio: #REF!
Name _ÍNDICE_ITEM: #REF!
Name _Inter_Imp: #REF!
Name _Interestadual: #REF!
Name _IPI_Próprio: #REF!
Name _ISSTIS: #REF!
Name _Meses_Diluição: #REF!
Name _MêsNúm: #REF!
Name _NCMsOK: #REF!
Name _Pagto: #REF!
Name _PTAX: #REF!
Name _PTAXZero: #REF!
Name _RangeUF: #REF!
Name _RegimeTIS: #REF!
Name _SEDÓLAR: #REF!
Name _SEREAL: #REF!
Name _Serv_SDWAN: #REF!
Name _SIMNÃO: #REF!
Name _Sites2: #REF!
Name _SVAVISTA: #REF!
Name _SvFat: #REF!
Name _SvFatM: #REF!
Name _SvFI: #REF!
Name _SVMENSAL: #REF!
Name _SvSDFatM: #REF!
Name _SvT: #REF!
Name _Tier2_InicioDetalhe: #REF!
Name _TipoProduto: #REF!
Name _UF: #REF!
Name _UF_D: #REF!
Name _UF_D_ICMS: #REF!
Name _UF_O: #REF!
Name _valida_Difal: #REF!
Name Aprovação: #REF!
Name ARP_REPLAY: #REF!
Name Arquitetos: #REF!
Name ÀVista: #REF!
Name Bene: SUM(#REF!)
Name CategoriasDeDespesas: #REF!
Name Fabricante_2T: #REF!
Name Firmware: #REF!
Name Fornecedor: #REF!
Name Fornecedor_2T: #REF!
Name Fornecedor_2Tsv: #REF!
Name Hedge1T: #REF!

Sheet RUNBOOK
A1: #VALUE!
A2: Requisição da Mudança | E2: Explicações de Como Preencher
A4: Título da Mudança: | B4: Implantação do Sdwan - Piloto | E4: Diz respeito ao que se trata esta mudança
A5: Solicitante da RDM: | B5: Projeto SD-WAN | E5: Responsável pela Mudança
A6: Motivo: | B6: Janela de migração | E6: Informe o motivo pelo qual a mudança deve ser realizada.
A7: Categoria da Mudança: | B7: Programada | E7: Tipo da Mudança, Programada, Emergencial e Não Programada
A8: Criticidade: | B8: ALTO | D8: =_xlfn.XLOOKUP(B8,List!I2:I4,List!J2:J4) | E8: Informe a criticidade da mudança, pode ser: ALTA, MÉDIA ou BAIXA.
A9: E-mail do Aprovador: | B9: Cliente | E9: Receber o "De Acordo" do Cliente após analisar as atividades a serem realizadas na RDM.
A10: Data da RDM: | B10: 45848 | E10: Data da Requisição feita pelo Cliente
A11: Executor da Mudança | E11: Explicações de Como Preencher
A13: Equipe Executora: | B13: ISD_B2B | E13: Informe a equipe principal desta mudança, equipe que irá executar a mudança.
A14: Serviço Envolvido na Mudança: | B14: Implantação do Sdwan | E14: Informe a que serviço a mudança se refere, ou seja, onde a mudança irá Causar o impacto principal
A15: Risco Identificado: | B15: Indisponibilidade da unidade. | E15: Informe as conseqüências caso a mudança não possa ser realizada.
A16: Impacto: | B16: ALTO | D16: =_xlfn.XLOOKUP(B16,List!I2:I4,List!J2:J4) | E16: Informe o impacto causado pela mudança.
A17: Previsão de início: | B17: 0.41666667 | E17: Informe a data de início da mudança.
A18: Previsão de término: | B18: 0.66666667 | E18: Informe a data de término da mudança.
A19: Tempo Da Janela | B19: =IF(B18>B17,B18-B17,1-B17+B18)
A20: Responsável Técnico: | B20: Felipe Begnami | E20: Informe o responsável principal pela execução dessa mudança.
A21: Aprovação da Área Responsável: | B21: Felipe Paixão | E21: Aprovador da Execução da Mudança
A22: Validação da RDM: | B22: Cliente | E22: O verificador deve ser o mesmo Solicitante da RDM (ou seja, quem abriu/demandou a mudança)exceto se este for o executor.
A23: Tempo Estimado de Atividade | B23: =SUM(D80,D105) | C23: =IF(B23>B19,"Fora da Janela","Dentro da Janela") | D23: =SUM(D80,D100)
A24: Atividade | B24: Step-by-Step
B25: Etapa | C25: Descrição | D25: Jornada HS | E25: Informe de forma detalhada a descrição da mudança.
B26: Step | C26: 1 | D26: 0.0069444444
B27: Tempo Estimado | C27: 0.0069444444
B28: Ação | C28: Instalação Física do Sdwan
B29: Status
B30: Responsável | C30: DELFIA
B32: Step | C32: 2 | D32: =C33+D26
B33: Tempo Estimado | C33: 0.0069444444
B34: Ação | C34: Atualização de Firmware
B35: Status
B36: Responsável | C36: DELFIA
B38: Step | C38: 3 | D38: =C39+D32
B39: Tempo Estimado | C39: 0.020833333
B40: Ação | C40: Identificação e Conectividade Física dos Links
B41: Status
B42: Responsável | C42: DELFIA
B44: Step | C44: 4 | D44: =C45+D38
B45: Tempo Estimado | C45: 0.0069444444
...

Sheet CADERNO DE TESTE
B5: SITE
B6: ID SDWAN-INTRAGOV: | C6: IG999
B7: ID SDWAN-VTV: | C7: TEST999
B8: ACRONIMO: | C8: TST
B9: SITE NAME:
B10: LOCALIDADE: | C10: Sao Paulo/SP
B11: TOPOLOGIA: | C11: SD-WAN
B12: MODELO DE SOLUÇÃO: | C12: G
B13: FORNECEDOR: | C13: Fortinet
B14: MODELO DE EQUIPAMENTO: | C14: FGT-81F
B15: REDUNDANCIA (HA) | C15: NÃO
B16: HOSTNAME PRIMARIO: | C16: fgt-test
B17: SERIAL NUMBER PRIMARIO: | C17: FG81FTEST
B18: IP-MGMT: | C18: 10.0.0.1
B19: POSSUI DHCP-SERVER: | C19: NÃO
B20: POSSUI DHCP-RELAY: | C20: NÃO
B21: POSSUI VLAN: | C21: SIM
... B23: VOIP - CPE OU FGT: | C23: N/A
B24: VOIP - NOME DO COLABORADOR QUE VALIDOU
B25: VOIP - TELEFONE FIXO DO COLABORADOR
B28: ITEM | C28: RESPONSÁVEL | D28: EXECUTOR | E28: STATUS | F28: OBS
B29: Certificar Registro de Licença - FortiGuard | C29: Vivo Vita | F29: get sys fortiguard-service status
B30: Certificar Saúde do Sdwan | C30: Vivo Vita | F30: get sys performance status
B31: Certificar Conectividade com FMG - Prodesp | C31: Vivo Vita | F31: diagnose fdsm central-mgmt-status
B32: Certificar Conectividade com FAZ - Prodesp | C32: Vivo Vita | F32: get sys fortianalyzer-connectivity status
B33: Certificar Conectividade FGCP - High Availability | C33: Vivo Vita | D33: Vivo Vita | E33: ✔️ Concluido | F33: get sys ha status
B34: Teste de Conectividade - Health Check Sdwan | C34: Vivo Vita | F34: diag sys sdwan health-check status
B35: Teste de VPN - Overlay e Mgmt | C35: Vivo Vita | F35: get ipsec tunnel list
B36: Certificar Alias e Description - WAN | C36: Vivo Vita | D36: Vivo Vita | E36: ✔️ Concluido | F36: show sys interface
B37: Teste FÍsico Das Interfaces - (WAN e LAN) | C37: Vivo Vita | F37: get sys interface physical
B38: Teste de IP Dinamico - Escopo DHCP | C38: Vivo Vita | F38: exec dhcp lease-list
B39: Teste de Conectividade - Lan | C39: Vivo Vita | F39: get sys arp
B40: Teste de Velocidade - Bandwidth | C40: Vivo Vita | D40: Vivo Vita | E40: ✔️ Concluido | F40: Site ESAQ
B41: Testes de Voz - Inter-Site (Entre Secretária) | C41: Cliente | D41: Cliente | E41: ⚠️Pendente
B42: Testes de Voz - Entre Ramais | C42: Cliente | D42: Cliente | E42: ⚠️Pendente
B43: Testes de Voz - Ligações Externa (Celular e/ou Call-Center) | C43: Cliente | D43: Cliente | E43: ⚠️Pendente
B44: Teste de Navegação Web - DIA | C44: Cliente | D44: Cliente | E44: ⚠️Pendente
B45: Teste de Navegação Web - SIA | C45: Cliente | D45: Cliente | E45: ⚠️Pendente
B46: Teste de Aplicação Cliente (VoIP, DNS, ERP, Cloud, Website) | C46: Cliente | D46: Cliente | E46: ⚠️Pendente
B47: Teste de Autenticação (Ldap, Radius, User Local) | C47: Cliente | D47: Cliente | E47: ⚠️Pendente
...

Sheet CARIMBO NOC
B5: TASK DO PROJETO
B7: 1 | C7: Description | D7: Info Device | E7: CARIMBO - SDWAN
C9: ID SDWAN-INTRAGOV: | D9: ='CADERNO DE TESTE'!C6 | E9: =_xlfn.CONCAT(C9," ",D9)
C10: ID SDWAN-VTV: | D10: ='CADERNO DE TESTE'!C7 | E10: =_xlfn.CONCAT(C10," ",D10)
C11: ACRONIMO: | D11: ='CADERNO DE TESTE'!C8 | E11: =UPPER(_xlfn.CONCAT(C11," ",D11))
C12: SITE NAME: | D12: ='CADERNO DE TESTE'!C9 | E12: =UPPER(_xlfn.CONCAT(C12," ",D12))
C13: LOCALIDADE: | D13: ='CADERNO DE TESTE'!C10 | E13: =UPPER(_xlfn.CONCAT(C13," ",D13))
C14: TOPOLOGIA: | D14: ='CADERNO DE TESTE'!C11 | E14: =_xlfn.CONCAT(C14," ",D14)
C15: MODELO DE SOLUÇÃO: | D15: ='CADERNO DE TESTE'!C12 | E15: =_xlfn.CONCAT(C15," ",D15)
C16: FORNECEDOR: | D16: ='CADERNO DE TESTE'!C13 | E16: =_xlfn.CONCAT(C16," ",D16)
C17: MODELO DE EQUIPAMENTO: | D17: ='CADERNO DE TESTE'!C14 | E17: =_xlfn.CONCAT(C17," ",D17)
C18: REDUNDANCIA (HA): | D18: ='CADERNO DE TESTE'!C15 | E18: =_xlfn.CONCAT(C18," ",D18)
C19: HOSTNAME PRIMARIO: | D19: =LOWER('CADERNO DE TESTE'!C16) | E19: =_xlfn.CONCAT(C19," ",D19)
C20: SERIAL NUMBER: | D20: ='CADERNO DE TESTE'!C17 | E20: =_xlfn.CONCAT(C20," ",D20)
C21: IP-MGMT: | D21: ='CADERNO DE TESTE'!C18 | E21: =_xlfn.CONCAT(C21," ",D21)
C22: POSSUI DHCP-SERVER: | D22: ='CADERNO DE TESTE'!C19 | E22: =_xlfn.CONCAT(C22," ",D22)
C23: POSSUI DHCP-RELAY: | D23: ='CADERNO DE TESTE'!C20 | E23: =_xlfn.CONCAT(C23," ",D23)
C24: POSSUI VLAN: | D24: ='CADERNO DE TESTE'!C21 | E24: =_xlfn.CONCAT(C24," ",D24)
C25: POSSUI MAIS DE UM IP NA LAN: | D25: ='CADERNO DE TESTE'!C22 | E25: =_xlfn.CONCAT(C25," ",D25)
C26: VOIP - CPE OU FGT: | D26: ='CADERNO DE TESTE'!C23 | E26: =_xlfn.CONCAT(C26," ",D26)
B28: 2 | C28: Description | D28: Info Device | E28: Conectividade SAI-BL
C30: INTERFACE: | D30: wan | E30: =_xlfn.CONCAT(C30," ",D30)
C31: CIRCUITO: | D31: SAI-BL | E31: =_xlfn.CONCAT(C31," ",D31)
C32: TEGNOLOGIA: | D32: INET1 | E32: =_xlfn.CONCAT(C32," ",D32)
C33: ID VANTIVE: | D33: 111 | E33: =_xlfn.CONCAT(C33," ",D33)
C34: VELOCIDADE: | D34: 100Mb | E34: =_xlfn.CONCAT(C34," ",D34)
C35: DESCRIPTION: | D35: SAI-BL_INET1_111_100 | E35: =_xlfn.CONCAT(C35," ",D35)
C36: IP WAN: | D36: 187.1.1.1 | E36: =_xlfn.CONCAT(C36," ",D36)
C37: REMOTO: | D37: 187.1.1.0 | E37: =_xlfn.CONCAT(C37," ",D37)
C39: Description | D39: Info Device | E39: Conectividade SAI-BLI
C41: INTERFACE: | E41: =_xlfn.CONCAT(C41," ",D41)
C42: CIRCUITO: | E42: =_xlfn.CONCAT(C42," ",D42)
C43: TEGNOLOGIA: | E43: =_xlfn.CONCAT(C43," ",D43)
C44: ID VANTIVE: | E44: =_xlfn.CONCAT(C44," ",D44)
C45: VELOCIDADE: | E45: =_xlfn.CONCAT(C45," ",D45)
C46: DESCRIPTION: | E46: =_xlfn.CONCAT(C46," ",D46)
C47: IP WAN: | E47: =_xlfn.CONCAT(C47," ",D47)
C48: REMOTO: | E48: =_xlfn.CONCAT(C48," ",D48)
C50: Description | D50: Info Device | E50: Conectividade SCM-MPLS1
C52: INTERFACE: | D52: lan3 | E52: =_xlfn.CONCAT(C52," ",D52)
...

Sheet TESTE_DE_BANDA_ESAQ
A7: SITE: | B7: https://www.brasilbandalarga.com.br/

Sheet List
A1: STATUS | C1: RESPOSÁVEL | E1: Status | F1: Responsável | G1: Criticidade | H1: Categoria da Mudança | I1: IMPACTO | L1: INTERFACE | N1: TECNOLOGIA DE LINK | P1: TECNOLOGIA DE LINK
C2: Vivo Vita | E2: ✔ Concluído | F2: VITA-IMP | G2: Baixa | H2: Programada | I2: BAIXO | J2: 5 | L2: lan1 | N2: SCM | P2: INET1
A3: ⚠️Pendente | C3: Cliente | E3: ⚠ Pendente | F3: CLIENTE | G3: Média | H3: Emergêncial | I3: MÉDIO | J3: 10 | L3: lan2 | N3: SAI-BL | P3: INET2
A4: ✔️ Concluido | E4: ❌ Cancelado | F4: VIVO-REGIONAL | G4: Alta | H4: Não Programada | I4: ALTO | J4: 15 | L4: lan3 | N4: SAI-BLI | P4: MPLS1
A5: ❌ Falhou | F5: VIVO-ATIVADO | L5: lan4 | N5: N/A | P5: MPLS2
A6: ℹ️ N/A | F6: VITA-FIELD | L6: port1
F7: VITA-NOC | L7: port2
L8: port3
L9: port4
L10: port5
L11: port6
L12: port7
L13: port8
L14: port9
E15: TOPOLOGIA: | F15: PRODUTO: | G15: MODELO DE SOLUÇÃO: | H15: FORNECEDOR: | I15: MODELO DE EQUIPAMENTO: | J15: REDUNDANCIA (HA) | L15: port10
E16: HUB | F16: SOLO | G16: P | H16: FORTINET | I16: FGT-40/41F | J16: SIM - PRINCIPAL | L16: port11
E17: SPK | F17: COMBO | G17: M | H17: CISCO | I17: FGT-60/61F | J17: SIM - SECUNDÁRIO | L17: port12
G18: G | H18: ARUBA | I18: FGT-70/71F | J18: NÃO | L18: port13
H19: HUAWEI | I19: FGT-80/81F | L19: port14
I20: FGT-100/101F | L20: port15
I21: FGT-200/201F | L21: port16
L22: port17
L23: port18
L24: port19
L25: port20
E26: DHCP - RESPOSTA | F26: VOIP - RESPOSTA | L26: internal1
E27: Sim | L27: internal2
E28: Não | F28: CPE | L28: internal3
F29: FGT | L29: internal4
F30: Não Possui Voip | L30: internal5
L31: internal6
L32: internal7
L33: internal8
L34: internal9
L35: internal10
L36: wan
L37: wan1
L38: wan2
L39: dmz
L40: ha1
...
